<?xml version="1.0"?>
<robot name="arm_2d">


    <material name="grey">
        <color rgba="0.7 0.7 0.7 1" />
    </material>

    <material name="blue">
        <color rgba="0.1 0.1 0.8 1" />
    </material>

    <material name="red">
        <color rgba="0.8 0.1 0.1 1" />
    </material>

    <link name="base_footprint" />

    <link name="base_link">
        <visual>
            <geometry>
                <box size="0.4 0.4 0.2" />
            </geometry>
            <origin xyz="0 0 0" rpy="0 0 0" />
            <material name="blue" />
        </visual>
    </link>

    <link name="arm_1_link">
        <visual>
            <geometry>
                <cylinder radius="0.1" length="0.8" />
            </geometry>
            <origin xyz="0 0 0.4" rpy="0 0 0" />
            <material name="grey" />
        </visual>
    </link>

    <link name="arm_2_link">
        <visual>
            <geometry>
                <cylinder radius="0.1" length="0.8" />
            </geometry>
            <origin xyz="0 0 0.4" rpy="0 0 0" />
            <material name="grey" />
        </visual>
    </link>

    <link name="arm_3_link">
        <visual>
            <geometry>
                <cylinder radius="0.1" length="0.8" />
            </geometry>
            <origin xyz="0 0.4 0" rpy="1.57 0 0" />
            <material name="grey" />
        </visual>
    </link>

    <link name="base_arm_1_link_hold">
        <visual>
            <geometry>
                <sphere radius="0.1" />
            </geometry>
            <origin xyz="0 0 0" rpy="0 0 0" />
            <material name="red" />
        </visual>
    </link>

    <link name="arm_1_arm_3_link_hold">
        <visual>
            <geometry>
                <sphere radius="0.1" />
            </geometry>
            <origin xyz="0 0 0" rpy="0 0 0" />
            <material name="red" />
        </visual>
    </link>

    <link name="arm_2_arm_3_link_hold">
        <visual>
            <geometry>
                <sphere radius="0.1" />
            </geometry>
            <origin xyz="0 0 0" rpy="0 0 0" />
            <material name="red" />
        </visual>
    </link>

    <joint name="base_joint" type="fixed">
        <parent link="base_footprint" />
        <child link="base_link" />
        <origin xyz="0 0 0" rpy="0 0 0" />
    </joint>

    <joint name="base_arm_1_joint" type="continuous">
        <parent link="base_link" />
        <child link="arm_1_link" />
        <origin xyz="0 0 0.1" rpy="0 0 0" />
        <axis xyz="0 1 0" />
    </joint>

    <joint name="arm_3_arm_2_joint" type="continuous">
        <parent link="arm_3_link" />
        <child link="arm_2_link" />
        <origin xyz="0 0.8 0" rpy="0 0 0" />
        <axis xyz="0 1 0" />
    </joint>

    <joint name="arm_1_arm_3_joint" type="continuous">
        <parent link="arm_1_link" />
        <child link="arm_3_link" />
        <origin xyz="0 0 0.8" rpy="0 0 0" />
        <axis xyz="0 0 1" />
    </joint>

    <joint name="base_arm_1_hold_joint" type="fixed">
        <parent link="base_link" />
        <child link="base_arm_1_link_hold" />
        <origin xyz="0 0 0.1" rpy="0 0 0" />
    </joint>

    <joint name="arm_1_arm_3_hold_joint" type="fixed">
        <parent link="arm_1_link" />
        <child link="arm_1_arm_3_link_hold" />
        <origin xyz="0 0 0.8" rpy="0 0 0" />
    </joint>

    <joint name="arm_2_arm_3_hold_joint" type="fixed">
        <parent link="arm_2_link" />
        <child link="arm_2_arm_3_link_hold" />
        <origin xyz="0 0 0" rpy="0 0 0" />
    </joint>

</robot>